venv/lib/python3.11/site-packages/dj_database_url-0.5.0.dist-info/DESCRIPTION.rst:8: [redirected permanently] http://www.12factor.net/backing-services to https://www.12factor.net/backing-services
venv/lib/python3.11/site-packages/pytz-2021.1.dist-info/DESCRIPTION.rst:521: [redirected permanently] http://cldr.unicode.org to https://cldr.unicode.org/
venv/lib/python3.11/site-packages/dj_database_url-0.5.0.dist-info/DESCRIPTION.rst:3: [redirected permanently] http://travis-ci.org/kennethreitz/dj-database-url to https://app.travis-ci.com/kennethreitz/dj-database-url
venv/lib/python3.11/site-packages/nose-1.3.7.dist-info/DESCRIPTION.rst:10: [redirected with Found] http://readthedocs.org/docs/nose/ to https://nose.readthedocs.io/en/latest/
venv/src/django-debug-toolbar/docs/changes.rst:25: [redirected permanently] https://beta.ruff.rs/ to https://docs.astral.sh/ruff/
venv/src/django-debug-toolbar/README.rst:53: [broken] https://django-debug-toolbar.readthedocs.io/: HTTPSConnectionPool(host='django-debug-toolbar.readthedocs.io', port=443): Max retries exceeded with url: / (Caused by SSLError(SSLEOFError(8, '[SSL: UNEXPECTED_EOF_WHILE_READING] EOF occurred in violation of protocol (_ssl.c:1006)')))
venv/src/django-debug-toolbar/docs/installation.rst:45: [redirected with Found] https://docs.djangoproject.com/en/stable/howto/static-files/ to https://docs.djangoproject.com/en/5.0/howto/static-files/
venv/src/django-debug-toolbar/docs/changes.rst:428: [redirected permanently] https://github.com/ambv/black to https://github.com/psf/black
venv/src/django-debug-toolbar/docs/panels.rst:150: [broken] https://github.com/brendangregg/FlameGraph/flamegraph.pl: 404 Client Error: Not Found for url: https://github.com/brendangregg/FlameGraph/flamegraph.pl
venv/src/django-debug-toolbar/docs/contributing.rst:23: [broken] https://github.com/git/git/blob/0afbf6caa5b16dcfa3074982e5b48e27d452dbbb/Documentation/config.txt#L1381: Anchor 'L1381' not found
venv/lib/python3.11/site-packages/autopep8-1.5.7.dist-info/AUTHORS.rst:5: [broken] https://github.com/gwelymernans: 404 Client Error: Not Found for url: https://github.com/gwelymernans
venv/lib/python3.11/site-packages/nose-1.3.7.dist-info/DESCRIPTION.rst:17: [broken] https://github.com/nose-devs/nose/tarball/master#egg=nose-dev: 'utf-8' codec can't decode byte 0x8b in position 1: invalid start byte
venv/src/django-debug-toolbar/README.rst:5: [redirected permanently] https://img.shields.io/pypi/djversions/django-debug-toolbar to https://img.shields.io/pypi/frameworkversions/django/django-debug-toolbar.svg
venv/src/django-debug-toolbar/docs/installation.rst:17: [redirected with Found] https://pip.pypa.io/ to https://pip.pypa.io/en/stable/
venv/src/django-debug-toolbar/README.rst:3: [redirected permanently] https://raw.github.com/jazzband/django-debug-toolbar/main/example/django-debug-toolbar.png to https://raw.githubusercontent.com/jazzband/django-debug-toolbar/main/example/django-debug-toolbar.png
venv/src/django-debug-toolbar/docs/contributing.rst:182: [broken] https://readthedocs.org/dashboard/django-debug-toolbar/versions/: 404 Client Error: Not Found for url: https://readthedocs.org/dashboard/django-debug-toolbar/versions/
venv/src/django-debug-toolbar/docs/panels.rst:256: [broken] https://requests.readthedocs.io/: HTTPSConnectionPool(host='requests.readthedocs.io', port=443): Max retries exceeded with url: / (Caused by SSLError(SSLEOFError(8, '[SSL: UNEXPECTED_EOF_WHILE_READING] EOF occurred in violation of protocol (_ssl.c:1006)')))
venv/src/django-debug-toolbar/docs/changes.rst:282: [broken] https://prettier.io/: ('Connection aborted.', ConnectionResetError(104, 'Connection reset by peer'))
venv/lib/python3.11/site-packages/pytz-2021.1.dist-info/DESCRIPTION.rst:567: [broken] https://tidelift.com/security: 403 Client Error: Forbidden for url: https://tidelift.com/security
venv/lib/python3.11/site-packages/pytz-2021.1.dist-info/DESCRIPTION.rst:53: [broken] https://tidelift.com/subscription/pkg/pypi-pytz?utm_source=pypi-pytz&utm_medium=referral&utm_campaign=enterprise&utm_term=repo: 403 Client Error: Forbidden for url: https://tidelift.com/subscription/pkg/pypi-pytz?utm_source=pypi-pytz&utm_medium=referral&utm_campaign=enterprise&utm_term=repo
venv/src/django-debug-toolbar/docs/contributing.rst:32: [broken] https://virtualenv.pypa.io/: HTTPSConnectionPool(host='virtualenv.pypa.io', port=443): Max retries exceeded with url: / (Caused by SSLError(SSLEOFError(8, '[SSL: UNEXPECTED_EOF_WHILE_READING] EOF occurred in violation of protocol (_ssl.c:1006)')))
venv/src/django-debug-toolbar/docs/contributing.rst:133: [redirected permanently] https://www.transifex.com/projects/p/django-debug-toolbar/ to https://explore.transifex.com
venv/lib/python3.11/site-packages/pytz-2021.1.dist-info/DESCRIPTION.rst:587: [broken] http://www.twinsun.com/tz/tz-link.htm: ('Connection aborted.', ConnectionResetError(104, 'Connection reset by peer'))
